[2024-04-29T05:38:38.090+0000] {taskinstance.py:1979} INFO - Dependencies all met for dep_context=non-requeueable deps ti=<TaskInstance: etl.create_tables scheduled__2024-04-26T00:00:00+00:00 [queued]>
[2024-04-29T05:38:38.205+0000] {taskinstance.py:1979} INFO - Dependencies all met for dep_context=requeueable deps ti=<TaskInstance: etl.create_tables scheduled__2024-04-26T00:00:00+00:00 [queued]>
[2024-04-29T05:38:38.219+0000] {taskinstance.py:2193} INFO - Starting attempt 1 of 1
[2024-04-29T05:38:38.375+0000] {taskinstance.py:2217} INFO - Executing <Task(PythonOperator): create_tables> on 2024-04-26 00:00:00+00:00
[2024-04-29T05:38:38.444+0000] {standard_task_runner.py:60} INFO - Started process 2399 to run task
[2024-04-29T05:38:38.466+0000] {standard_task_runner.py:87} INFO - Running: ['***', 'tasks', 'run', 'etl', 'create_tables', 'scheduled__2024-04-26T00:00:00+00:00', '--job-id', '51', '--raw', '--subdir', 'DAGS_FOLDER/etl.py', '--cfg-path', '/tmp/tmpf018ppsa']
[2024-04-29T05:38:38.497+0000] {standard_task_runner.py:88} INFO - Job 51: Subtask create_tables
[2024-04-29T05:38:38.918+0000] {task_command.py:423} INFO - Running <TaskInstance: etl.create_tables scheduled__2024-04-26T00:00:00+00:00 [running]> on host 422c09390d6c
[2024-04-29T05:38:39.531+0000] {taskinstance.py:2513} INFO - Exporting env vars: AIRFLOW_CTX_DAG_OWNER='***' AIRFLOW_CTX_DAG_ID='etl' AIRFLOW_CTX_TASK_ID='create_tables' AIRFLOW_CTX_EXECUTION_DATE='2024-04-26T00:00:00+00:00' AIRFLOW_CTX_TRY_NUMBER='1' AIRFLOW_CTX_DAG_RUN_ID='scheduled__2024-04-26T00:00:00+00:00'
[2024-04-29T05:38:39.608+0000] {taskinstance.py:2731} ERROR - Task failed with exception
Traceback (most recent call last):
  File "/home/airflow/.local/lib/python3.8/site-packages/airflow/models/taskinstance.py", line 444, in _execute_task
    result = _execute_callable(context=context, **execute_callable_kwargs)
  File "/home/airflow/.local/lib/python3.8/site-packages/airflow/models/taskinstance.py", line 414, in _execute_callable
    return execute_callable(context=context, **execute_callable_kwargs)
  File "/home/airflow/.local/lib/python3.8/site-packages/airflow/operators/python.py", line 200, in execute
    return_value = self.execute_callable()
  File "/home/airflow/.local/lib/python3.8/site-packages/airflow/operators/python.py", line 217, in execute_callable
    return self.python_callable(*self.op_args, **self.op_kwargs)
  File "/opt/airflow/dags/etl.py", line 30, in _create_tables
    conn = hook.get_conn()
  File "/home/airflow/.local/lib/python3.8/site-packages/airflow/providers/postgres/hooks/postgres.py", line 131, in get_conn
    conn = deepcopy(self.connection or self.get_connection(conn_id))
  File "/home/airflow/.local/lib/python3.8/site-packages/airflow/hooks/base.py", line 82, in get_connection
    conn = Connection.get_connection_from_secrets(conn_id)
  File "/home/airflow/.local/lib/python3.8/site-packages/airflow/models/connection.py", line 514, in get_connection_from_secrets
    raise AirflowNotFoundException(f"The conn_id `{conn_id}` isn't defined")
airflow.exceptions.AirflowNotFoundException: The conn_id `my_postgres_conn` isn't defined
[2024-04-29T05:38:39.634+0000] {taskinstance.py:1149} INFO - Marking task as FAILED. dag_id=etl, task_id=create_tables, execution_date=20240426T000000, start_date=20240429T053838, end_date=20240429T053839
[2024-04-29T05:38:39.694+0000] {standard_task_runner.py:107} ERROR - Failed to execute job 51 for task create_tables (The conn_id `my_postgres_conn` isn't defined; 2399)
[2024-04-29T05:38:39.789+0000] {local_task_job_runner.py:234} INFO - Task exited with return code 1
[2024-04-29T05:38:39.951+0000] {taskinstance.py:3312} INFO - 0 downstream tasks scheduled from follow-on schedule check
